Workbook

Sheet README
A1: Africa's mobile-money frontier: market-selection model
A2: Question: which two sub-Saharan markets should a Kenya-based mobile-money operator enter by 2030?
A4: How to use
A5: 1 | B5: Change blue cells on Inputs (assumptions) or Data (market facts). Everything else is a formula and recalculates.
A6: 2 | B6: Read Summary for the ranking, Cases for the NPV by market and scenario, Sensitivity for what moves the answer, Checks for integrity.
A7: 3 | B7: Robustness and PyRef hold results estimated in Python (analysis/model.py). They are static. Re-run the script to refresh them.
A8: Sheets
A9: Summary | B9: Ranking of candidate markets with attractiveness, ease, quadrant, pools and NPV.
A10: Inputs | B10: All assumptions with a tag and a source or rationale. Includes calibration of revenue per user to company disclosures.
A11: Data | B11: Findex 2024 and World Development Indicators for 34 markets, plus judgement inputs (proximity) and the World Bank fragility score.
A12: Forecast | B12: Adoption to 2030 in three scenarios using a logistic curve.
A13: Pools | B13: Users x revenue per user, winnable revenue, pool growth, and cost scale.
A14: Scorecard | B14: Min-max scoring, attractiveness and ease, priority = sqrt(A x E), rank, discount rate, quadrant.
A15: Cases | B15: Year-by-year business case for the top five markets in three scenarios; break-even share.
A16: Sensitivity | B16: NPV grids for the top three markets: share x revenue per user, and margin x fixed cost.
A17: Colour code | B17: Blue = input. Black = formula. Green = link to another sheet. Yellow fill = key assumption or key output.
A18: Tags | B18: [S] sourced, [A] analyst assumption, [E] estimated in Python, [S/A] sourced with analyst adjustment.
A19: Not a valuation | B19: The business case is an entry screen for choosing between markets. It ignores tax, working capital and detailed currency paths.

Sheet Summary
A1: Where should a Kenyan mobile-money operator expand next? Summary of results
A2: Everything here is a live link into the model. Change an input on the Inputs sheet and this page updates.
A3: Model integrity: | B3: =Checks!D29 -> ALL CHECKS PASS
A5: Rank | B5: Market | C5: ISO3 | D5: Attractiveness (0-100) | E5: Ease of entry (0-100) | F5: Priority score | G5: Quadrant | H5: Adoption 2024 | I5: Adoption 2030 Base | J5: Revenue pool 2030 Base ($m) | K5: Winnable revenue 2030 Base ($m) | L5: Discount rate | M5: NPV Base ($m, top five)
A6: 1 | B6: =INDEX(Scorecard!$A$6:$A$39,MATCH(1,Scorecard!$AS$6:$AS$39,0)) -> Tanzania | C6: =INDEX(Scorecard!$B$6:$B$39,MATCH(1,Scorecard!$AS$6:$AS$39,0)) -> TZA | D6: =INDEX(Scorecard!$AC$6:$AC$39,MATCH(1,Scorecard!$AS$6:$AS$39,0)) -> 54.317622 | E6: =INDEX(Scorecard!$AQ$6:$AQ$39,MATCH(1,Scorecard!$AS$6:$AS$39,0)) -> 79.420807 | F6: =INDEX(Scorecard!$AR$6:$AR$39,MATCH(1,Scorecard!$AS$6:$AS$39,0)) -> 65.680662 | G6: =INDEX(Scorecard!$AU$6:$AU$39,MATCH(1,Scorecard!$AS$6:$AS$39,0)) -> Prioritise | H6: =INDEX(Data!$E$6:$E$39,MATCH(1,Scorecard!$AS$6:$AS$39,0)) -> 0.52853984 | I6: =INDEX(Forecast!$J$6:$J$39,MATCH(1,Scorecard!$AS$6:$AS$39,0)) -> 0.76614066 | J6: =INDEX(Pools!$L$6:$L$39,MATCH(1,Scorecard!$AS$6:$AS$39,0)) -> 672.62386 | K6: =INDEX(Pools!$R$6:$R$39,MATCH(1,Scorecard!$AS$6:$AS$39,0)) -> 45.210565 | L6: =INDEX(Scorecard!$AT$6:$AT$39,MATCH(1,Scorecard!$AS$6:$AS$39,0)) -> 0.12799263 | M6: =IFERROR(INDEX(Cases!$F$6:$F$10,MATCH(C6,Cases!$C$6:$C$10,0)),"") -> 13.478933
A7: 2 | B7: =INDEX(Scorecard!$A$6:$A$39,MATCH(2,Scorecard!$AS$6:$AS$39,0)) -> Cote d'Ivoire | C7: =INDEX(Scorecard!$B$6:$B$39,MATCH(2,Scorecard!$AS$6:$AS$39,0)) -> CIV | D7: =INDEX(Scorecard!$AC$6:$AC$39,MATCH(2,Scorecard!$AS$6:$AS$39,0)) -> 51.384197 | E7: =INDEX(Scorecard!$AQ$6:$AQ$39,MATCH(2,Scorecard!$AS$6:$AS$39,0)) -> 71.547241 | F7: =INDEX(Scorecard!$AR$6:$AR$39,MATCH(2,Scorecard!$AS$6:$AS$39,0)) -> 60.633303 | G7: =INDEX(Scorecard!$AU$6:$AU$39,MATCH(2,Scorecard!$AS$6:$AS$39,0)) -> Prioritise | H7: =INDEX(Data!$E$6:$E$39,MATCH(2,Scorecard!$AS$6:$AS$39,0)) -> 0.53381779 | I7: =INDEX(Forecast!$J$6:$J$39,MATCH(2,Scorecard!$AS$6:$AS$39,0)) -> 0.7699166 | J7: =INDEX(Pools!$L$6:$L$39,MATCH(2,Scorecard!$AS$6:$AS$39,0)) -> 408.8148 | K7: =INDEX(Pools!$R$6:$R$39,MATCH(2,Scorecard!$AS$6:$AS$39,0)) -> 27.308259 | L7: =INDEX(Scorecard!$AT$6:$AT$39,MATCH(2,Scorecard!$AS$6:$AS$39,0)) -> 0.12533993 | M7: =IFERROR(INDEX(Cases!$F$6:$F$10,MATCH(C7,Cases!$C$6:$C$10,0)),"") -> -10.323053
A8: 3 | B8: =INDEX(Scorecard!$A$6:$A$39,MATCH(3,Scorecard!$AS$6:$AS$39,0)) -> Uganda | C8: =INDEX(Scorecard!$B$6:$B$39,MATCH(3,Scorecard!$AS$6:$AS$39,0)) -> UGA | D8: =INDEX(Scorecard!$AC$6:$AC$39,MATCH(3,Scorecard!$AS$6:$AS$39,0)) -> 47.416766 | E8: =INDEX(Scorecard!$AQ$6:$AQ$39,MATCH(3,Scorecard!$AS$6:$AS$39,0)) -> 77.268162 | F8: =INDEX(Scorecard!$AR$6:$AR$39,MATCH(3,Scorecard!$AS$6:$AS$39,0)) -> 60.529385 | G8: =INDEX(Scorecard!$AU$6:$AU$39,MATCH(3,Scorecard!$AS$6:$AS$39,0)) -> Prioritise | H8: =INDEX(Data!$E$6:$E$39,MATCH(3,Scorecard!$AS$6:$AS$39,0)) -> 0.67738295 | I8: =INDEX(Forecast!$J$6:$J$39,MATCH(3,Scorecard!$AS$6:$AS$39,0)) -> 0.85986066 | J8: =INDEX(Pools!$L$6:$L$39,MATCH(3,Scorecard!$AS$6:$AS$39,0)) -> 516.18182 | K8: =INDEX(Pools!$R$6:$R$39,MATCH(3,Scorecard!$AS$6:$AS$39,0)) -> 28.630609 | L8: =INDEX(Scorecard!$AT$6:$AT$39,MATCH(3,Scorecard!$AS$6:$AS$39,0)) -> 0.12717103 | M8: =IFERROR(INDEX(Cases!$F$6:$F$10,MATCH(C8,Cases!$C$6:$C$10,0)),"") -> -29.90096
A9: 4 | B9: =INDEX(Scorecard!$A$6:$A$39,MATCH(4,Scorecard!$AS$6:$AS$39,0)) -> Congo, Dem. Rep. | C9: =INDEX(Scorecard!$B$6:$B$39,MATCH(4,Scorecard!$AS$6:$AS$39,0)) -> COD | D9: =INDEX(Scorecard!$AC$6:$AC$39,MATCH(4,Scorecard!$AS$6:$AS$39,0)) -> 63.786352 | E9: =INDEX(Scorecard!$AQ$6:$AQ$39,MATCH(4,Scorecard!$AS$6:$AS$39,0)) -> 56.945809 | F9: =INDEX(Scorecard!$AR$6:$AR$39,MATCH(4,Scorecard!$AS$6:$AS$39,0)) -> 60.269108 | G9: =INDEX(Scorecard!$AU$6:$AU$39,MATCH(4,Scorecard!$AS$6:$AS$39,0)) -> Big but hard | H9: =INDEX(Data!$E$6:$E$39,MATCH(4,Scorecard!$AS$6:$AS$39,0)) -> 0.35118239 | I9: =INDEX(Forecast!$J$6:$J$39,MATCH(4,Scorecard!$AS$6:$AS$39,0)) -> 0.61266217 | J9: =INDEX(Pools!$L$6:$L$39,MATCH(4,Scorecard!$AS$6:$AS$39,0)) -> 620.39175 | K9: =INDEX(Pools!$R$6:$R$39,MATCH(4,Scorecard!$AS$6:$AS$39,0)) -> 50.385198 | L9: =INDEX(Scorecard!$AT$6:$AT$39,MATCH(4,Scorecard!$AS$6:$AS$39,0)) -> 0.16466025 | M9: =IFERROR(INDEX(Cases!$F$6:$F$10,MATCH(C9,Cases!$C$6:$C$10,0)),"") -> 2.1813478
A10: 5 | B10: =INDEX(Scorecard!$A$6:$A$39,MATCH(5,Scorecard!$AS$6:$AS$39,0)) -> Benin | C10: =INDEX(Scorecard!$B$6:$B$39,MATCH(5,Scorecard!$AS$6:$AS$39,0)) -> BEN | D10: =INDEX(Scorecard!$AC$6:$AC$39,MATCH(5,Scorecard!$AS$6:$AS$39,0)) -> 43.37119 | E10: =INDEX(Scorecard!$AQ$6:$AQ$39,MATCH(5,Scorecard!$AS$6:$AS$39,0)) -> 71.033009 | F10: =INDEX(Scorecard!$AR$6:$AR$39,MATCH(5,Scorecard!$AS$6:$AS$39,0)) -> 55.504829 | G10: =INDEX(Scorecard!$AU$6:$AU$39,MATCH(5,Scorecard!$AS$6:$AS$39,0)) -> Easy but small | H10: =INDEX(Data!$E$6:$E$39,MATCH(5,Scorecard!$AS$6:$AS$39,0)) -> 0.44872852 | I10: =INDEX(Forecast!$J$6:$J$39,MATCH(5,Scorecard!$AS$6:$AS$39,0)) -> 0.70402795 | J10: =INDEX(Pools!$L$6:$L$39,MATCH(5,Scorecard!$AS$6:$AS$39,0)) -> 129.37709 | K10: =INDEX(Pools!$R$6:$R$39,MATCH(5,Scorecard!$AS$6:$AS$39,0)) -> 9.5111853 | L10: =INDEX(Scorecard!$AT$6:$AT$39,MATCH(5,Scorecard!$AS$6:$AS$39,0)) -> 0.12375724 | M10: =IFERROR(INDEX(Cases!$F$6:$F$10,MATCH(C10,Cases!$C$6:$C$10,0)),"") -> -40.6569
A11: 6 | B11: =INDEX(Scorecard!$A$6:$A$39,MATCH(6,Scorecard!$AS$6:$AS$39,0)) -> Senegal | C11: =INDEX(Scorecard!$B$6:$B$39,MATCH(6,Scorecard!$AS$6:$AS$39,0)) -> SEN | D11: =INDEX(Scorecard!$AC$6:$AC$39,MATCH(6,Scorecard!$AS$6:$AS$39,0)) -> 41.41908 | E11: =INDEX(Scorecard!$AQ$6:$AQ$39,MATCH(6,Scorecard!$AS$6:$AS$39,0)) -> 74.128645 | F11: =INDEX(Scorecard!$AR$6:$AR$39,MATCH(6,Scorecard!$AS$6:$AS$39,0)) -> 55.410651 | G11: =INDEX(Scorecard!$AU$6:$AU$39,MATCH(6,Scorecard!$AS$6:$AS$39,0)) -> Easy but small | H11: =INDEX(Data!$E$6:$E$39,MATCH(6,Scorecard!$AS$6:$AS$39,0)) -> 0.66912649 | I11: =INDEX(Forecast!$J$6:$J$39,MATCH(6,Scorecard!$AS$6:$AS$39,0)) -> 0.85527644 | J11: =INDEX(Pools!$L$6:$L$39,MATCH(6,Scorecard!$AS$6:$AS$39,0)) -> 223.56055 | K11: =INDEX(Pools!$R$6:$R$39,MATCH(6,Scorecard!$AS$6:$AS$39,0)) -> 12.545741 | L11: =INDEX(Scorecard!$AT$6:$AT$39,MATCH(6,Scorecard!$AS$6:$AS$39,0)) -> 0.1286206 | M11: =IFERROR(INDEX(Cases!$F$6:$F$10,MATCH(C11,Cases!$C$6:$C$10,0)),"")
A12: 7 | B12: =INDEX(Scorecard!$A$6:$A$39,MATCH(7,Scorecard!$AS$6:$AS$39,0)) -> Zambia | C12: =INDEX(Scorecard!$B$6:$B$39,MATCH(7,Scorecard!$AS$6:$AS$39,0)) -> ZMB | D12: =INDEX(Scorecard!$AC$6:$AC$39,MATCH(7,Scorecard!$AS$6:$AS$39,0)) -> 39.798722 | E12: =INDEX(Scorecard!$AQ$6:$AQ$39,MATCH(7,Scorecard!$AS$6:$AS$39,0)) -> 75.539456 | F12: =INDEX(Scorecard!$AR$6:$AR$39,MATCH(7,Scorecard!$AS$6:$AS$39,0)) -> 54.830409 | G12: =INDEX(Scorecard!$AU$6:$AU$39,MATCH(7,Scorecard!$AS$6:$AS$39,0)) -> Easy but small | H12: =INDEX(Data!$E$6:$E$39,MATCH(7,Scorecard!$AS$6:$AS$39,0)) -> 0.69310751 | I12: =INDEX(Forecast!$J$6:$J$39,MATCH(7,Scorecard!$AS$6:$AS$39,0)) -> 0.86841881 | J12: =INDEX(Pools!$L$6:$L$39,MATCH(7,Scorecard!$AS$6:$AS$39,0)) -> 258.31363 | K12: =INDEX(Pools!$R$6:$R$39,MATCH(7,Scorecard!$AS$6:$AS$39,0)) -> 14.00703 | L12: =INDEX(Scorecard!$AT$6:$AT$39,MATCH(7,Scorecard!$AS$6:$AS$39,0)) -> 0.13304865 | M12: =IFERROR(INDEX(Cases!$F$6:$F$10,MATCH(C12,Cases!$C$6:$C$10,0)),"")
A13: 8 | B13: =INDEX(Scorecard!$A$6:$A$39,MATCH(8,Scorecard!$AS$6:$AS$39,0)) -> Togo | C13: =INDEX(Scorecard!$B$6:$B$39,MATCH(8,Scorecard!$AS$6:$AS$39,0)) -> TGO | D13: =INDEX(Scorecard!$AC$6:$AC$39,MATCH(8,Scorecard!$AS$6:$AS$39,0)) -> 44.886226 | E13: =INDEX(Scorecard!$AQ$6:$AQ$39,MATCH(8,Scorecard!$AS$6:$AS$39,0)) -> 66.784967 | F13: =INDEX(Scorecard!$AR$6:$AR$39,MATCH(8,Scorecard!$AS$6:$AS$39,0)) -> 54.751485 | G13: =INDEX(Scorecard!$AU$6:$AU$39,MATCH(8,Scorecard!$AS$6:$AS$39,0)) -> Easy but small | H13: =INDEX(Data!$E$6:$E$39,MATCH(8,Scorecard!$AS$6:$AS$39,0)) -> 0.47991838 | I13: =INDEX(Forecast!$J$6:$J$39,MATCH(8,Scorecard!$AS$6:$AS$39,0)) -> 0.72948133 | J13: =INDEX(Pools!$L$6:$L$39,MATCH(8,Scorecard!$AS$6:$AS$39,0)) -> 82.344863 | K13: =INDEX(Pools!$R$6:$R$39,MATCH(8,Scorecard!$AS$6:$AS$39,0)) -> 5.8508673 | L13: =INDEX(Scorecard!$AT$6:$AT$39,MATCH(8,Scorecard!$AS$6:$AS$39,0)) -> 0.12571994 | M13: =IFERROR(INDEX(Cases!$F$6:$F$10,MATCH(C13,Cases!$C$6:$C$10,0)),"")
A14: 9 | B14: =INDEX(Scorecard!$A$6:$A$39,MATCH(9,Scorecard!$AS$6:$AS$39,0)) -> Madagascar | C14: =INDEX(Scorecard!$B$6:$B$39,MATCH(9,Scorecard!$AS$6:$AS$39,0)) -> MDG | D14: =INDEX(Scorecard!$AC$6:$AC$39,MATCH(9,Scorecard!$AS$6:$AS$39,0)) -> 53.522103 | E14: =INDEX(Scorecard!$AQ$6:$AQ$39,MATCH(9,Scorecard!$AS$6:$AS$39,0)) -> 54.901383 | F14: =INDEX(Scorecard!$AR$6:$AR$39,MATCH(9,Scorecard!$AS$6:$AS$39,0)) -> 54.207356 | G14: =INDEX(Scorecard!$AU$6:$AU$39,MATCH(9,Scorecard!$AS$6:$AS$39,0)) -> Big but hard | H14: =INDEX(Data!$E$6:$E$39,MATCH(9,Scorecard!$AS$6:$AS$39,0)) -> 0.19355017 | I14: =INDEX(Forecast!$J$6:$J$39,MATCH(9,Scorecard!$AS$6:$AS$39,0)) -> 0.41223283 | J14: =INDEX(Pools!$L$6:$L$39,MATCH(9,Scorecard!$AS$6:$AS$39,0)) -> 117.79208 | K14: =INDEX(Pools!$R$6:$R$39,MATCH(9,Scorecard!$AS$6:$AS$39,0)) -> 11.032172 | L14: =INDEX(Scorecard!$AT$6:$AT$39,MATCH(9,Scorecard!$AS$6:$AS$39,0)) -> 0.13175402 | M14: =IFERROR(INDEX(Cases!$F$6:$F$10,MATCH(C14,Cases!$C$6:$C$10,0)),"")
A15: 10 | B15: =INDEX(Scorecard!$A$6:$A$39,MATCH(10,Scorecard!$AS$6:$AS$39,0)) -> Liberia | C15: =INDEX(Scorecard!$B$6:$B$39,MATCH(10,Scorecard!$AS$6:$AS$39,0)) -> LBR | D15: =INDEX(Scorecard!$AC$6:$AC$39,MATCH(10,Scorecard!$AS$6:$AS$39,0)) -> 46.72092 | E15: =INDEX(Scorecard!$AQ$6:$AQ$39,MATCH(10,Scorecard!$AS$6:$AS$39,0)) -> 61.940661 | F15: =INDEX(Scorecard!$AR$6:$AR$39,MATCH(10,Scorecard!$AS$6:$AS$39,0)) -> 53.795211 | G15: =INDEX(Scorecard!$AU$6:$AU$39,MATCH(10,Scorecard!$AS$6:$AS$39,0)) -> Prioritise | H15: =INDEX(Data!$E$6:$E$39,MATCH(10,Scorecard!$AS$6:$AS$39,0)) -> 0.47529254 | I15: =INDEX(Forecast!$J$6:$J$39,MATCH(10,Scorecard!$AS$6:$AS$39,0)) -> 0.72580701 | J15: =INDEX(Pools!$L$6:$L$39,MATCH(10,Scorecard!$AS$6:$AS$39,0)) -> 40.90941 | K15: =INDEX(Pools!$R$6:$R$39,MATCH(10,Scorecard!$AS$6:$AS$39,0)) -> 2.921683 | L15: =INDEX(Scorecard!$AT$6:$AT$39,MATCH(10,Scorecard!$AS$6:$AS$39,0)) -> 0.13096788 | M15: =IFERROR(INDEX(Cases!$F$6:$F$10,MATCH(C15,Cases!$C$6:$C$10,0)),"")
A16: 11 | B16: =INDEX(Scorecard!$A$6:$A$39,MATCH(11,Scorecard!$AS$6:$AS$39,0)) -> Ghana | C16: =INDEX(Scorecard!$B$6:$B$39,MATCH(11,Scorecard!$AS$6:$AS$39,0)) -> GHA | D16: =INDEX(Scorecard!$AC$6:$AC$39,MATCH(11,Scorecard!$AS$6:$AS$39,0)) -> 39.312784 | E16: =INDEX(Scorecard!$AQ$6:$AQ$39,MATCH(11,Scorecard!$AS$6:$AS$39,0)) -> 68.744969 | F16: =INDEX(Scorecard!$AR$6:$AR$39,MATCH(11,Scorecard!$AS$6:$AS$39,0)) -> 51.986114 | G16: =INDEX(Scorecard!$AU$6:$AU$39,MATCH(11,Scorecard!$AS$6:$AS$39,0)) -> Easy but small | H16: =INDEX(Data!$E$6:$E$39,MATCH(11,Scorecard!$AS$6:$AS$39,0)) -> 0.78281364 | I16: =INDEX(Forecast!$J$6:$J$39,MATCH(11,Scorecard!$AS$6:$AS$39,0)) -> 0.91329134 | J16: =INDEX(Pools!$L$6:$L$39,MATCH(11,Scorecard!$AS$6:$AS$39,0)) -> 584.03577 | K16: =INDEX(Pools!$R$6:$R$39,MATCH(11,Scorecard!$AS$6:$AS$39,0)) -> 27.533692 | L16: =INDEX(Scorecard!$AT$6:$AT$39,MATCH(11,Scorecard!$AS$6:$AS$39,0)) -> 0.1473334 | M16: =IFERROR(INDEX(Cases!$F$6:$F$10,MATCH(C16,Cases!$C$6:$C$10,0)),"")
A17: 12 | B17: =INDEX(Scorecard!$A$6:$A$39,MATCH(12,Scorecard!$AS$6:$AS$39,0)) -> Guinea | C17: =INDEX(Scorecard!$B$6:$B$39,MATCH(12,Scorecard!$AS$6:$AS$39,0)) -> GIN | D17: =INDEX(Scorecard!$AC$6:$AC$39,MATCH(12,Scorecard!$AS$6:$AS$39,0)) -> 45.636315 | E17: =INDEX(Scorecard!$AQ$6:$AQ$39,MATCH(12,Scorecard!$AS$6:$AS$39,0)) -> 58.825665 | F17: =INDEX(Scorecard!$AR$6:$AR$39,MATCH(12,Scorecard!$AS$6:$AS$39,0)) -> 51.812996 | G17: =INDEX(Scorecard!$AU$6:$AU$39,MATCH(12,Scorecard!$AS$6:$AS$39,0)) -> Prioritise | H17: =INDEX(Data!$E$6:$E$39,MATCH(12,Scorecard!$AS$6:$AS$39,0)) -> 0.2582194 | I17: =INDEX(Forecast!$J$6:$J$39,MATCH(12,Scorecard!$AS$6:$AS$39,0)) -> 0.50427951 | J17: =INDEX(Pools!$L$6:$L$39,MATCH(12,Scorecard!$AS$6:$AS$39,0)) -> 79.592719 | K17: =INDEX(Pools!$R$6:$R$39,MATCH(12,Scorecard!$AS$6:$AS$39,0)) -> 7.0481954 | L17: =INDEX(Scorecard!$AT$6:$AT$39,MATCH(12,Scorecard!$AS$6:$AS$39,0)) -> 0.13015186 | M17: =IFERROR(INDEX(Cases!$F$6:$F$10,MATCH(C17,Cases!$C$6:$C$10,0)),"")
A18: 13 | B18: =INDEX(Scorecard!$A$6:$A$39,MATCH(13,Scorecard!$AS$6:$AS$39,0)) -> Malawi | C18: =INDEX(Scorecard!$B$6:$B$39,MATCH(13,Scorecard!$AS$6:$AS$39,0)) -> MWI | D18: =INDEX(Scorecard!$AC$6:$AC$39,MATCH(13,Scorecard!$AS$6:$AS$39,0)) -> 44.375404 | E18: =INDEX(Scorecard!$AQ$6:$AQ$39,MATCH(13,Scorecard!$AS$6:$AS$39,0)) -> 57.564393 | F18: =INDEX(Scorecard!$AR$6:$AR$39,MATCH(13,Scorecard!$AS$6:$AS$39,0)) -> 50.5415 | G18: =INDEX(Scorecard!$AU$6:$AU$39,MATCH(13,Scorecard!$AS$6:$AS$39,0)) -> Easy but small | H18: =INDEX(Data!$E$6:$E$39,MATCH(13,Scorecard!$AS$6:$AS$39,0)) -> 0.47399198 | I18: =INDEX(Forecast!$J$6:$J$39,MATCH(13,Scorecard!$AS$6:$AS$39,0)) -> 0.72476782 | J18: =INDEX(Pools!$L$6:$L$39,MATCH(13,Scorecard!$AS$6:$AS$39,0)) -> 162.22223 | K18: =INDEX(Pools!$R$6:$R$39,MATCH(13,Scorecard!$AS$6:$AS$39,0)) -> 11.6023 | L18: =INDEX(Scorecard!$AT$6:$AT$39,MATCH(13,Scorecard!$AS$6:$AS$39,0)) -> 0.14773061 | M18: =IFERROR(INDEX(Cases!$F$6:$F$10,MATCH(C18,Cases!$C$6:$C$10,0)),"")
A19: 14 | B19: =INDEX(Scorecard!$A$6:$A$39,MATCH(14,Scorecard!$AS$6:$AS$39,0)) -> Cameroon | C19: =INDEX(Scorecard!$B$6:$B$39,MATCH(14,Scorecard!$AS$6:$AS$39,0)) -> CMR | D19: =INDEX(Scorecard!$AC$6:$AC$39,MATCH(14,Scorecard!$AS$6:$AS$39,0)) -> 48.177479 | E19: =INDEX(Scorecard!$AQ$6:$AQ$39,MATCH(14,Scorecard!$AS$6:$AS$39,0)) -> 51.923556 | F19: =INDEX(Scorecard!$AR$6:$AR$39,MATCH(14,Scorecard!$AS$6:$AS$39,0)) -> 50.015458 | G19: =INDEX(Scorecard!$AU$6:$AU$39,MATCH(14,Scorecard!$AS$6:$AS$39,0)) -> Big but hard | H19: =INDEX(Data!$E$6:$E$39,MATCH(14,Scorecard!$AS$6:$AS$39,0)) -> 0.55065452 | I19: =INDEX(Forecast!$J$6:$J$39,MATCH(14,Scorecard!$AS$6:$AS$39,0)) -> 0.78171317 | J19: =INDEX(Pools!$L$6:$L$39,MATCH(14,Scorecard!$AS$6:$AS$39,0)) -> 330.66089 | K19: =INDEX(Pools!$R$6:$R$39,MATCH(14,Scorecard!$AS$6:$AS$39,0)) -> 21.64823 | L19: =INDEX(Scorecard!$AT$6:$AT$39,MATCH(14,Scorecard!$AS$6:$AS$39,0)) -> 0.17139103 | M19: =IFERROR(INDEX(Cases!$F$6:$F$10,MATCH(C19,Cases!$C$6:$C$10,0)),"")
A20: 15 | B20: =INDEX(Scorecard!$A$6:$A$39,MATCH(15,Scorecard!$AS$6:$AS$39,0)) -> South Africa | C20: =INDEX(Scorecard!$B$6:$B$39,MATCH(15,Scorecard!$AS$6:$AS$39,0)) -> ZAF | D20: =INDEX(Scorecard!$AC$6:$AC$39,MATCH(15,Scorecard!$AS$6:$AS$39,0)) -> 41.456257 | E20: =INDEX(Scorecard!$AQ$6:$AQ$39,MATCH(15,Scorecard!$AS$6:$AS$39,0)) -> 58.540753 | F20: =INDEX(Scorecard!$AR$6:$AR$39,MATCH(15,Scorecard!$AS$6:$AS$39,0)) -> 49.263379 | G20: =INDEX(Scorecard!$AU$6:$AU$39,MATCH(15,Scorecard!$AS$6:$AS$39,0)) -> Easy but small | H20: =INDEX(Data!$E$6:$E$39,MATCH(15,Scorecard!$AS$6:$AS$39,0)) -> 0.31623202 | I20: =INDEX(Forecast!$J$6:$J$39,MATCH(15,Scorecard!$AS$6:$AS$39,0)) -> 0.5747407 | J20: =INDEX(Pools!$L$6:$L$39,MATCH(15,Scorecard!$AS$6:$AS$39,0)) -> 377.49392 | K20: =INDEX(Pools!$R$6:$R$39,MATCH(15,Scorecard!$AS$6:$AS$39,0)) -> 31.699666 | L20: =INDEX(Scorecard!$AT$6:$AT$39,MATCH(15,Scorecard!$AS$6:$AS$39,0)) -> 0.13736149 | M20: =IFERROR(INDEX(Cases!$F$6:$F$10,MATCH(C20,Cases!$C$6:$C$10,0)),"")
A21: 16 | B21: =INDEX(Scorecard!$A$6:$A$39,MATCH(16,Scorecard!$AS$6:$AS$39,0)) -> Mozambique | C21: =INDEX(Scorecard!$B$6:$B$39,MATCH(16,Scorecard!$AS$6:$AS$39,0)) -> MOZ | D21: =INDEX(Scorecard!$AC$6:$AC$39,MATCH(16,Scorecard!$AS$6:$AS$39,0)) -> 49.845521 | E21: =INDEX(Scorecard!$AQ$6:$AQ$39,MATCH(16,Scorecard!$AS$6:$AS$39,0)) -> 46.423596 | F21: =INDEX(Scorecard!$AR$6:$AR$39,MATCH(16,Scorecard!$AS$6:$AS$39,0)) -> 48.10414 | G21: =INDEX(Scorecard!$AU$6:$AU$39,MATCH(16,Scorecard!$AS$6:$AS$39,0)) -> Big but hard | H21: =INDEX(Data!$E$6:$E$39,MATCH(16,Scorecard!$AS$6:$AS$39,0)) -> 0.45720986 | I21: =INDEX(Forecast!$J$6:$J$39,MATCH(16,Scorecard!$AS$6:$AS$39,0)) -> 0.7111102 | J21: =INDEX(Pools!$L$6:$L$39,MATCH(16,Scorecard!$AS$6:$AS$39,0)) -> 211.26568 | K21: =INDEX(Pools!$R$6:$R$39,MATCH(16,Scorecard!$AS$6:$AS$39,0)) -> 15.389805 | L21: =INDEX(Scorecard!$AT$6:$AT$39,MATCH(16,Scorecard!$AS$6:$AS$39,0)) -> 0.16962438 | M21: =IFERROR(INDEX(Cases!$F$6:$F$10,MATCH(C21,Cases!$C$6:$C$10,0)),"")
A22: 17 | B22: =INDEX(Scorecard!$A$6:$A$39,MATCH(17,Scorecard!$AS$6:$AS$39,0)) -> Mali | C22: =INDEX(Scorecard!$B$6:$B$39,MATCH(17,Scorecard!$AS$6:$AS$39,0)) -> MLI | D22: =INDEX(Scorecard!$AC$6:$AC$39,MATCH(17,Scorecard!$AS$6:$AS$39,0)) -> 50.112931 | E22: =INDEX(Scorecard!$AQ$6:$AQ$39,MATCH(17,Scorecard!$AS$6:$AS$39,0)) -> 45.048962 | F22: =INDEX(Scorecard!$AR$6:$AR$39,MATCH(17,Scorecard!$AS$6:$AS$39,0)) -> 47.51353 | G22: =INDEX(Scorecard!$AU$6:$AU$39,MATCH(17,Scorecard!$AS$6:$AS$39,0)) -> Big but hard | H22: =INDEX(Data!$E$6:$E$39,MATCH(17,Scorecard!$AS$6:$AS$39,0)) -> 0.48387616 | I22: =INDEX(Forecast!$J$6:$J$39,MATCH(17,Scorecard!$AS$6:$AS$39,0)) -> 0.73259813 | J22: =INDEX(Pools!$L$6:$L$39,MATCH(17,Scorecard!$AS$6:$AS$39,0)) -> 198.02577 | K22: =INDEX(Pools!$R$6:$R$39,MATCH(17,Scorecard!$AS$6:$AS$39,0)) -> 14.008502 | L22: =INDEX(Scorecard!$AT$6:$AT$39,MATCH(17,Scorecard!$AS$6:$AS$39,0)) -> 0.16914497 | M22: =IFERROR(INDEX(Cases!$F$6:$F$10,MATCH(C22,Cases!$C$6:$C$10,0)),"")
A23: 18 | B23: =INDEX(Scorecard!$A$6:$A$39,MATCH(18,Scorecard!$AS$6:$AS$39,0)) -> Sierra Leone | C23: =INDEX(Scorecard!$B$6:$B$39,MATCH(18,Scorecard!$AS$6:$AS$39,0)) -> SLE | D23: =INDEX(Scorecard!$AC$6:$AC$39,MATCH(18,Scorecard!$AS$6:$AS$39,0)) -> 41.233896 | E23: =INDEX(Scorecard!$AQ$6:$AQ$39,MATCH(18,Scorecard!$AS$6:$AS$39,0)) -> 53.356799 | F23: =INDEX(Scorecard!$AR$6:$AR$39,MATCH(18,Scorecard!$AS$6:$AS$39,0)) -> 46.905316 | G23: =INDEX(Scorecard!$AU$6:$AU$39,MATCH(18,Scorecard!$AS$6:$AS$39,0)) -> Deprioritise | H23: =INDEX(Data!$E$6:$E$39,MATCH(18,Scorecard!$AS$6:$AS$39,0)) -> 0.32195726 | I23: =INDEX(Forecast!$J$6:$J$39,MATCH(18,Scorecard!$AS$6:$AS$39,0)) -> 0.58116821 | J23: =INDEX(Pools!$L$6:$L$39,MATCH(18,Scorecard!$AS$6:$AS$39,0)) -> 58.945239 | K23: =INDEX(Pools!$R$6:$R$39,MATCH(18,Scorecard!$AS$6:$AS$39,0)) -> 4.9232272 | L23: =INDEX(Scorecard!$AT$6:$AT$39,MATCH(18,Scorecard!$AS$6:$AS$39,0)) -> 0.14893204 | M23: =IFERROR(INDEX(Cases!$F$6:$F$10,MATCH(C23,Cases!$C$6:$C$10,0)),"")
A24: 19 | B24: =INDEX(Scorecard!$A$6:$A$39,MATCH(19,Scorecard!$AS$6:$AS$39,0)) -> Congo, Rep. | C24: =INDEX(Scorecard!$B$6:$B$39,MATCH(19,Scorecard!$AS$6:$AS$39,0)) -> COG | D24: =INDEX(Scorecard!$AC$6:$AC$39,MATCH(19,Scorecard!$AS$6:$AS$39,0)) -> 36.947665 | E24: =INDEX(Scorecard!$AQ$6:$AQ$39,MATCH(19,Scorecard!$AS$6:$AS$39,0)) -> 59.293913 | F24: =INDEX(Scorecard!$AR$6:$AR$39,MATCH(19,Scorecard!$AS$6:$AS$39,0)) -> 46.80568 | G24: =INDEX(Scorecard!$AU$6:$AU$39,MATCH(19,Scorecard!$AS$6:$AS$39,0)) -> Easy but small | H24: =INDEX(Data!$E$6:$E$39,MATCH(19,Scorecard!$AS$6:$AS$39,0)) -> 0.51592118 | I24: =INDEX(Forecast!$J$6:$J$39,MATCH(19,Scorecard!$AS$6:$AS$39,0)) -> 0.7569571 | J24: =INDEX(Pools!$L$6:$L$39,MATCH(19,Scorecard!$AS$6:$AS$39,0)) -> 77.635606 | K24: =INDEX(Pools!$R$6:$R$39,MATCH(19,Scorecard!$AS$6:$AS$39,0)) -> 5.2956252 | L24: =INDEX(Scorecard!$AT$6:$AT$39,MATCH(19,Scorecard!$AS$6:$AS$39,0)) -> 0.15781991 | M24: =IFERROR(INDEX(Cases!$F$6:$F$10,MATCH(C24,Cases!$C$6:$C$10,0)),"")
A25: 20 | B25: =INDEX(Scorecard!$A$6:$A$39,MATCH(20,Scorecard!$AS$6:$AS$39,0)) -> Nigeria | C25: =INDEX(Scorecard!$B$6:$B$39,MATCH(20,Scorecard!$AS$6:$AS$39,0)) -> NGA | D25: =INDEX(Scorecard!$AC$6:$AC$39,MATCH(20,Scorecard!$AS$6:$AS$39,0)) -> 68.731423 | E25: =INDEX(Scorecard!$AQ$6:$AQ$39,MATCH(20,Scorecard!$AS$6:$AS$39,0)) -> 30.497663 | F25: =INDEX(Scorecard!$AR$6:$AR$39,MATCH(20,Scorecard!$AS$6:$AS$39,0)) -> 45.783706 | G25: =INDEX(Scorecard!$AU$6:$AU$39,MATCH(20,Scorecard!$AS$6:$AS$39,0)) -> Big but hard | H25: =INDEX(Data!$E$6:$E$39,MATCH(20,Scorecard!$AS$6:$AS$39,0)) -> 0.32790752 | I25: =INDEX(Forecast!$J$6:$J$39,MATCH(20,Scorecard!$AS$6:$AS$39,0)) -> 0.58775638 | J25: =INDEX(Pools!$L$6:$L$39,MATCH(20,Scorecard!$AS$6:$AS$39,0)) -> 1320.9712 | K25: =INDEX(Pools!$R$6:$R$39,MATCH(20,Scorecard!$AS$6:$AS$39,0)) -> 109.70977 | L25: =INDEX(Scorecard!$AT$6:$AT$39,MATCH(20,Scorecard!$AS$6:$AS$39,0)) -> 0.18958428 | M25: =IFERROR(INDEX(Cases!$F$6:$F$10,MATCH(C25,Cases!$C$6:$C$10,0)),"")
A26: 21 | B26: =INDEX(Scorecard!$A$6:$A$39,MATCH(21,Scorecard!$AS$6:$AS$39,0)) -> Burkina Faso | C26: =INDEX(Scorecard!$B$6:$B$39,MATCH(21,Scorecard!$AS$6:$AS$39,0)) -> BFA | D26: =INDEX(Scorecard!$AC$6:$AC$39,MATCH(21,Scorecard!$AS$6:$AS$39,0)) -> 46.83604 | E26: =INDEX(Scorecard!$AQ$6:$AQ$39,MATCH(21,Scorecard!$AS$6:$AS$39,0)) -> 38.75993 | F26: =INDEX(Scorecard!$AR$6:$AR$39,MATCH(21,Scorecard!$AS$6:$AS$39,0)) -> 42.607061 | G26: =INDEX(Scorecard!$AU$6:$AU$39,MATCH(21,Scorecard!$AS$6:$AS$39,0)) -> Big but hard | H26: =INDEX(Data!$E$6:$E$39,MATCH(21,Scorecard!$AS$6:$AS$39,0)) -> 0.44157364 | I26: =INDEX(Forecast!$J$6:$J$39,MATCH(21,Scorecard!$AS$6:$AS$39,0)) -> 0.69795622 | J26: =INDEX(Pools!$L$6:$L$39,MATCH(21,Scorecard!$AS$6:$AS$39,0)) -> 174.90816 | K26: =INDEX(Pools!$R$6:$R$39,MATCH(21,Scorecard!$AS$6:$AS$39,0)) -> 12.957196 | L26: =INDEX(Scorecard!$AT$6:$AT$39,MATCH(21,Scorecard!$AS$6:$AS$39,0)) -> 0.17225921 | M26: =IFERROR(INDEX(Cases!$F$6:$F$10,MATCH(C26,Cases!$C$6:$C$10,0)),"")
A27: 22 | B27: =INDEX(Scorecard!$A$6:$A$39,MATCH(22,Scorecard!$AS$6:$AS$39,0)) -> Chad | C27: =INDEX(Scorecard!$B$6:$B$39,MATCH(22,Scorecard!$AS$6:$AS$39,0)) -> TCD | D27: =INDEX(Scorecard!$AC$6:$AC$39,MATCH(22,Scorecard!$AS$6:$AS$39,0)) -> 44.952903 | E27: =INDEX(Scorecard!$AQ$6:$AQ$39,MATCH(22,Scorecard!$AS$6:$AS$39,0)) -> 35.626108 | F27: =INDEX(Scorecard!$AR$6:$AR$39,MATCH(22,Scorecard!$AS$6:$AS$39,0)) -> 40.018708 | G27: =INDEX(Scorecard!$AU$6:$AU$39,MATCH(22,Scorecard!$AS$6:$AS$39,0)) -> Deprioritise | H27: =INDEX(Data!$E$6:$E$39,MATCH(22,Scorecard!$AS$6:$AS$39,0)) -> 0.13335894 | I27: =INDEX(Forecast!$J$6:$J$39,MATCH(22,Scorecard!$AS$6:$AS$39,0)) -> 0.31019278 | J27: =INDEX(Pools!$L$6:$L$39,MATCH(22,Scorecard!$AS$6:$AS$39,0)) -> 51.557008 | K27: =INDEX(Pools!$R$6:$R$39,MATCH(22,Scorecard!$AS$6:$AS$39,0)) -> 5.0736873 | L27: =INDEX(Scorecard!$AT$6:$AT$39,MATCH(22,Scorecard!$AS$6:$AS$39,0)) -> 0.15464262 | M27: =IFERROR(INDEX(Cases!$F$6:$F$10,MATCH(C27,Cases!$C$6:$C$10,0)),"")
A28: 23 | B28: =INDEX(Scorecard!$A$6:$A$39,MATCH(23,Scorecard!$AS$6:$AS$39,0)) -> Ethiopia | C28: =INDEX(Scorecard!$B$6:$B$39,MATCH(23,Scorecard!$AS$6:$AS$39,0)) -> ETH | D28: =INDEX(Scorecard!$AC$6:$AC$39,MATCH(23,Scorecard!$AS$6:$AS$39,0)) -> 58.126283 | E28: =INDEX(Scorecard!$AQ$6:$AQ$39,MATCH(23,Scorecard!$AS$6:$AS$39,0)) -> 26.919982 | F28: =INDEX(Scorecard!$AR$6:$AR$39,MATCH(23,Scorecard!$AS$6:$AS$39,0)) -> 39.557028 | G28: =INDEX(Scorecard!$AU$6:$AU$39,MATCH(23,Scorecard!$AS$6:$AS$39,0)) -> Big but hard | H28: =INDEX(Data!$E$6:$E$39,MATCH(23,Scorecard!$AS$6:$AS$39,0)) -> 0.094548896 | I28: =INDEX(Forecast!$J$6:$J$39,MATCH(23,Scorecard!$AS$6:$AS$39,0)) -> 0.23380419 | J28: =INDEX(Pools!$L$6:$L$39,MATCH(23,Scorecard!$AS$6:$AS$39,0)) -> 103.8991 | K28: =INDEX(Pools!$R$6:$R$39,MATCH(23,Scorecard!$AS$6:$AS$39,0)) -> 10.542931 | L28: =INDEX(Scorecard!$AT$6:$AT$39,MATCH(23,Scorecard!$AS$6:$AS$39,0)) -> 0.17933966 | M28: =IFERROR(INDEX(Cases!$F$6:$F$10,MATCH(C28,Cases!$C$6:$C$10,0)),"")
A29: 24 | B29: =INDEX(Scorecard!$A$6:$A$39,MATCH(24,Scorecard!$AS$6:$AS$39,0)) -> Zimbabwe | C29: =INDEX(Scorecard!$B$6:$B$39,MATCH(24,Scorecard!$AS$6:$AS$39,0)) -> ZWE | D29: =INDEX(Scorecard!$AC$6:$AC$39,MATCH(24,Scorecard!$AS$6:$AS$39,0)) -> 42.640538 | E29: =INDEX(Scorecard!$AQ$6:$AQ$39,MATCH(24,Scorecard!$AS$6:$AS$39,0)) -> 35.856925 | F29: =INDEX(Scorecard!$AR$6:$AR$39,MATCH(24,Scorecard!$AS$6:$AS$39,0)) -> 39.1019 | G29: =INDEX(Scorecard!$AU$6:$AU$39,MATCH(24,Scorecard!$AS$6:$AS$39,0)) -> Deprioritise | H29: =INDEX(Data!$E$6:$E$39,MATCH(24,Scorecard!$AS$6:$AS$39,0)) -> 0.43331737 | I29: =INDEX(Forecast!$J$6:$J$39,MATCH(24,Scorecard!$AS$6:$AS$39,0)) -> 0.6908366 | J29: =INDEX(Pools!$L$6:$L$39,MATCH(24,Scorecard!$AS$6:$AS$39,0)) -> 159.41589 | K29: =INDEX(Pools!$R$6:$R$39,MATCH(24,Scorecard!$AS$6:$AS$39,0)) -> 11.913423 | L29: =INDEX(Scorecard!$AT$6:$AT$39,MATCH(24,Scorecard!$AS$6:$AS$39,0)) -> 0.177662 | M29: =IFERROR(INDEX(Cases!$F$6:$F$10,MATCH(C29,Cases!$C$6:$C$10,0)),"")
A30: 25 | B30: =INDEX(Scorecard!$A$6:$A$39,MATCH(25,Scorecard!$AS$6:$AS$39,0)) -> Niger | C30: =INDEX(Scorecard!$B$6:$B$39,MATCH(25,Scorecard!$AS$6:$AS$39,0)) -> NER | D30: =INDEX(Scorecard!$AC$6:$AC$39,MATCH(25,Scorecard!$AS$6:$AS$39,0)) -> 45.033287 | E30: =INDEX(Scorecard!$AQ$6:$AQ$39,MATCH(25,Scorecard!$AS$6:$AS$39,0)) -> 25.295115 | F30: =INDEX(Scorecard!$AR$6:$AR$39,MATCH(25,Scorecard!$AS$6:$AS$39,0)) -> 33.750884 | G30: =INDEX(Scorecard!$AU$6:$AU$39,MATCH(25,Scorecard!$AS$6:$AS$39,0)) -> Deprioritise | H30: =INDEX(Data!$E$6:$E$39,MATCH(25,Scorecard!$AS$6:$AS$39,0)) -> 0.057003706 | I30: =INDEX(Forecast!$J$6:$J$39,MATCH(25,Scorecard!$AS$6:$AS$39,0)) -> 0.15012976 | J30: =INDEX(Pools!$L$6:$L$39,MATCH(25,Scorecard!$AS$6:$AS$39,0)) -> 16.560831 | K30: =INDEX(Pools!$R$6:$R$39,MATCH(25,Scorecard!$AS$6:$AS$39,0)) -> 1.7295544 | L30: =INDEX(Scorecard!$AT$6:$AT$39,MATCH(25,Scorecard!$AS$6:$AS$39,0)) -> 0.16309859 | M30: =IFERROR(INDEX(Cases!$F$6:$F$10,MATCH(C30,Cases!$C$6:$C$10,0)),"")
A32: Home market for reference:
A33: Kenya mobile money adoption 2024 | D33: =INDEX(Data!$E$6:$E$39,MATCH("KEN",Data!$B$6:$B$39,0)) -> 0.87499411
A34: Candidate markets scored (34 markets with 2024 data; home market and markets under the size screen excluded) | D34: =SUM(Data!AB6:AB39) -> 25

Sheet Inputs
A1: Inputs and assumptions
A2: Blue = input you can change. Tags: [S] sourced, [A] analyst assumption, [E] estimated in Python, [S/A] sourced with analyst adjustment.
A4: Input | B4: Unit | C4: Low | D4: Base | E4: High | F4: Tag | G4: Source or rationale
A5: 1. Timeline and forecast
A6: Base year (latest Findex survey) | B6: year | D6: 2024 | F6: [S] | G6: S1: Global Findex 2025 reports the 2024 survey round.
A7: Target year | B7: year | D7: 2030 | F7: [A] | G7: Planning horizon for the expansion decision.
A8: Years from base to target | B8: years | D8: =D7-D6 -> 6 | F8: calc
A9: Adoption ceiling in forecasts | B9: % of adults | D9: 0.92 | F9: [A] | G9: Just above Kenya's 87.5% (S1). Keeps the logistic curve from passing near-universal use.
A10: Minimum market size to be a candidate | B10: adults | D10: 3000000 | F10: [A] | G10: Below this, a regional platform cannot cover its fixed costs (see Pools column V).
A11: Pooled growth of logit(adoption) | B11: per year | D11: 0.17872706 | F11: [E] | G11: Median of country trends 2014-2024 (analysis/model.py). Back-test: beats country-specific trends (Robustness sheet).
A12: Weight on a country's own trend | B12: 0 to 1 | D12: 0 | F12: [E] | G12: Chosen by back-test: 0 gave the lowest 2024 forecast error. Raise it to give each country its own growth rate.
A13: Floor on growth | B13: per year | D13: 0 | F13: [A]
A14: Cap on growth | B14: per year | D14: 0.5 | F14: [A]
A15: 2. Scenarios
A16: Growth multiplier on adoption trend | B16: x | C16: 0.5 | D16: 1 | E16: 1.5 | F16: [A] | G16: Low halves the trend; High raises it by half. Back-test showed the Base trend over-predicted 2024 by 2.8 points on average.
A17: Revenue per active user in the reference market (Kenya income, mobile-led) | B17: USD per year | C17: 15 | D17: 25 | E17: 32 | F17: [S/A] | G17: S4: Airtel Money East Africa revenue per customer about $24.7. S3: M-Pesa about $32 per active user. Low = price compression; Airtel Money Nigeria is only about $3.3 (S4).
A18: Operator's share of NEW users by 2030 | B18: % | C18: 0.08 | D18: 0.15 | E18: 0.22 | F18: [A] | G18: What a well-funded challenger wins of adults who start using mobile money after 2024. Tested through the break-even share.
A19: Operator's share of EXISTING users | B19: % | C19: 0.015 | D19: 0.03 | E19: 0.05 | F19: [A] | G19: Switching or multi-homing by people who already use mobile money.
A20: Scenario weight for expected NPV | B20: % | C20: 0.25 | D20: 0.5 | E20: 0.25 | F20: [A] | G20: Judgement weights; the Low and High cases are symmetric around Base.
A21: 3. Revenue per user by market
A22: Income elasticity of revenue per user | B22: x | D22: 0.35 | F22: [A] | G22: Revenue per user rises less than proportionally with income (Francophone Africa earns more per customer than its income implies: S4).
A23: Income factor floor | B23: x | D23: 0.5 | F23: [A]
A24: Income factor cap | B24: x | D24: 1.3 | F24: [A]
A25: Elasticity to mobile-led share (mobile money / any account) | B25: x | D25: 1 | F25: [S/A] | G25: Bank-led markets earn far less per mobile money customer: Airtel Money Nigeria about $3.3 against $24.7 in East Africa (S4).
A26: Structure factor floor | B26: x | D26: 0.25 | F26: [A]
A27: Structure factor cap | B27: x | D27: 1 | F27: [A]
A28: 4. Business case for the entrant (USD millions unless stated)
A29: Contribution margin after agent commissions and variable cost | B29: % of revenue | D29: 0.5 | F29: [A] | G29: Mobile money is high-margin once agent commissions are paid; tested in Sensitivity.
A30: Fixed operating cost per year (reference-size market) | B30: $m | D30: 12 | F30: [A] | G30: Team, compliance, technology and brand. Scaled by market size (below).
A31: Acquisition cost per new operator user | B31: $ | D31: 3 | F31: [A] | G31: Agent onboarding and promotions.
A32: Launch investment (licence, platform, agent seeding), reference-size market | B32: $m | D32: 20 | F32: [A] | G32: Spent in 2026, one year before launch. Assumes a build or partnership entry, not an acquisition.
A33: Terminal value multiple on 2035 EBITDA | B33: x | D33: 5 | F33: [A]
A34: Reference market size for cost scaling | B34: adults | D34: 20000000 | F34: [A]
A35: Cost-scaling exponent | B35: x | D35: 0.4 | F35: [A] | G35: Costs rise with market size, but less than proportionally.
A36: Cost scale floor | B36: x | D36: 0.6 | F36: [A]
A37: Cost scale cap | B37: x | D37: 2 | F37: [A]
A38: Discount rate, base (USD) | B38: % | D38: 0.12 | F38: [A]
A39: Premium for weak macro stability (at score 0) | B39: % | D39: 0.04 | F39: [A]
A40: Premium for fragility (at score 0) | B40: % | D40: 0.04 | F40: [A] | G40: Scaled by the World Bank FY26 fragile-situations flag (S5).
A41: Share of target users reached, 2027 (launch year) | B41: % | D41: 0.1 | F41: [A]
...

Sheet Data
A1: Market data: 34 sub-Saharan African markets with Global Findex 2024 results
A2: Sources: S1 Global Findex 2025 (survey 2024); S2 World Development Indicators (updated 8 Oct 2026); S5 World Bank FY26 fragile-situations list. Blank = not available.
D4: Findex (S1) | J4: WDI (S2) | T4: Findex segments (S1) | W4: Judgement / World Bank (S5)
A5: Country | B5: ISO3 | C5: Income group (World Bank) | D5: Adults 2024 | E5: Mobile money account 2024 | F5: Any account 2024 | G5: Financial-institution account 2024 | H5: Digital merchant payment 2024 | I5: Mobile money account 2017 | J5: GDP per capita, PPP (2021 intl $) | K5: Urban population % | L5: Mobile subscriptions per 100 | M5: Internet users % | N5: Electricity access % | O5: Remittances % of GDP | P5: Population growth % a year | Q5: Inflation, average 2022-24 % | R5: Currency depreciation, average 2022-24 % a year | S5: GDP growth, average 2022-24 % | T5: Gender gap in mobile money, pp (men minus women) | U5: Income gap, pp (richest 60% minus poorest 40%) | V5: Rural gap, pp (urban minus rural) | W5: Proximity to Kenya (0-100) [A] | X5: Institutional stability (0-100) [S] | Y5: Own-trend growth of logit(adoption) per year | Z5: Home market | AA5: Meets size screen | AB5: Candidate
A6: Benin | B6: BEN | C6: Lower middle income | D6: 8207504 | E6: 0.44872852 | F6: 0.51843206 | G6: 0.19906178 | H6: 0.067646851 | I6: 0.18093838 | J6: 3901.3259 | K6: 52.545535 | L6: 125.94087 | M6: 33.983799 | N6: 59 | O6: 1.720825 | P6: 2.4617536 | Q6: 1.7501368 | R6: 2.9729476 | S6: 6.68628 | T6: 10.173517 | U6: 16.364479 | V6: 1.7812899 | W6: 20 | X6: 100 | Y6: 0.35001352 | Z6: =IF(B6="KEN",1,0) -> 0 | AA6: =IF(D6>=Inputs!$D$10,1,0) -> 1 | AB6: =IF(AND(Z6=0,AA6=1),1,0) -> 1
A7: Botswana | B7: BWA | C7: Upper middle income | D7: 1679590 | E7: 0.51617816 | F7: 0.61438469 | G7: 0.41604356 | H7: 0.25596427 | I7: 0.24378307 | J7: 18107.614 | K7: 67.462354 | L7: 163.99992 | M7: 57.4595 | N7: 80.2 | O7: 0.66523525 | P7: 1.6353841 | Q7: 6.5171781 | R7: 6.7186259 | S7: 1.9713985 | T7: 4.3509577 | U7: 23.16161 | V7: 1.4630648 | W7: 20 | X7: 100 | Y7: 0.13346244 | Z7: =IF(B7="KEN",1,0) -> 0 | AA7: =IF(D7>=Inputs!$D$10,1,0) -> 0 | AB7: =IF(AND(Z7=0,AA7=1),1,0) -> 0
A8: Burkina Faso | B8: BFA | C8: Low income | D8: 13262560 | E8: 0.44157364 | F8: 0.51427491 | G8: 0.20549892 | H8: 0.12044409 | I8: 0.33022799 | J8: 2548.5025 | K8: 28.335251 | L8: 116.58959 | M8: 28.252701 | N8: 34 | O8: 2.5727498 | P8: 2.2459773 | Q8: 6.4079877 | R8: 2.9775832 | S8: 3.1536549 | T8: 13.167098 | U8: 18.91277 | V8: 20.202327 | W8: 20 | X8: 0 | Y8: 0.26293923 | Z8: =IF(B8="KEN",1,0) -> 0 | AA8: =IF(D8>=Inputs!$D$10,1,0) -> 1 | AB8: =IF(AND(Z8=0,AA8=1),1,0) -> 1
A9: Cameroon | B9: CMR | C9: Lower middle income | D9: 16524096 | E9: 0.55065452 | F9: 0.60873791 | G9: 0.20997299 | H9: 0.20307798 | I9: 0.1513783 | J9: 4916.9335 | K9: 55.403175 | L9: 108.21313 | M9: 46.258801 | N9: 72 | O9: 1.2949265 | P9: 2.6126829 | Q9: 6.0546015 | R9: 2.9775832 | S9: 3.5363567 | T9: 14.60422 | U9: 26.161748 | V9: 23.508297 | W9: 20 | X9: 0 | Y9: 0.41137771 | Z9: =IF(B9="KEN",1,0) -> 0 | AA9: =IF(D9>=Inputs!$D$10,1,0) -> 1 | AB9: =IF(AND(Z9=0,AA9=1),1,0) -> 1
A10: Chad | B10: TCD | C10: Low income | D10: 10289880 | E10: 0.13335894 | F10: 0.2089836 | G10: 0.1500209 | H10: 0.050241056 | I10: 0.1523341 | J10: 2430.733 | K10: 26.931529 | L10: 72.928978 | M10: 12.6269 | N10: 13.4 | P10: 4.9485303 | Q10: 8.5079637 | R10: 2.9775832 | S10: 4.360139 | T10: 3.5387781 | U10: 2.7392581 | V10: 8.4392212 | W10: 20 | X10: 40 | Y10: 0.066901946 | Z10: =IF(B10="KEN",1,0) -> 0 | AA10: =IF(D10>=Inputs!$D$10,1,0) -> 1 | AB10: =IF(AND(Z10=0,AA10=1),1,0) -> 1
A11: Comoros | B11: COM | C11: Lower middle income | D11: 532331 | E11: 0.14093786 | F11: 0.45459397 | G11: 0.40847664 | H11: 0.067846207 | J11: 3556.0384 | K11: 33.539222 | L11: 109.85563 | M11: 32.517502 | N11: 91.7 | O11: 20.844476 | P11: 1.8918279 | Q11: 8.6525657 | R11: 2.9557096 | S11: 2.98038 | T11: 8.5239143 | U11: 5.9612696 | V11: -4.7260982 | W11: 20 | X11: 40 | Z11: =IF(B11="KEN",1,0) -> 0 | AA11: =IF(D11>=Inputs!$D$10,1,0) -> 0 | AB11: =IF(AND(Z11=0,AA11=1),1,0) -> 0
A12: Congo, Dem. Rep. | B12: COD | C12: Low income | D12: 57033055 | E12: 0.35118239 | F12: 0.39214012 | G12: 0.13506865 | H12: 0.074124188 | I12: 0.16096341 | J12: 1601.7093 | K12: 44.74558 | L12: 58.532153 | M12: 19.6735 | N12: 22.5 | O12: 2.6424157 | P12: 3.2425763 | R12: 8.1168694 | S12: 7.9823962 | T12: 13.179323 | U12: 20.056672 | V12: 18.851614 | W12: 100 | X12: 0 | Y12: 0.15043772 | Z12: =IF(B12="KEN",1,0) -> 0 | AA12: =IF(D12>=Inputs!$D$10,1,0) -> 1 | AB12: =IF(AND(Z12=0,AA12=1),1,0) -> 1
A13: Congo, Rep. | B13: COG | C13: Lower middle income | D13: 3655093 | E13: 0.51592118 | F13: 0.55576039 | G13: 0.14720001 | H13: 0.099257358 | I13: 0.062384391 | J13: 6152.5651 | K13: 63.886611 | L13: 95.531932 | M13: 47.251598 | N13: 53 | P13: 2.3982908 | Q13: 3.4788751 | R13: 2.9775832 | S13: 1.8274032 | T13: 8.7040271 | U13: 18.47605 | V13: 14.286252 | W13: 20 | X13: 40 | Y13: 0.41640328 | Z13: =IF(B13="KEN",1,0) -> 0 | AA13: =IF(D13>=Inputs!$D$10,1,0) -> 1 | AB13: =IF(AND(Z13=0,AA13=1),1,0) -> 1
A14: Cote d'Ivoire | B14: CIV | C14: Lower middle income | D14: 18301587 | E14: 0.53381779 | F14: 0.57567627 | G14: 0.1682522 | H14: 0.091596039 | I14: 0.34053173 | J14: 6747.038 | K14: 53.973311 | L14: 183.87599 | M14: 41.432199 | N14: 72.9 | O14: 2.0327233 | P14: 2.436182 | Q14: 4.3512605 | R14: 2.9775832 | S14: 6.3398062 | T14: 8.8148407 | U14: 22.03366 | V14: 17.408349 | W14: 20 | X14: 100 | Y14: 0.11919423 | Z14: =IF(B14="KEN",1,0) -> 0 | AA14: =IF(D14>=Inputs!$D$10,1,0) -> 1 | AB14: =IF(AND(Z14=0,AA14=1),1,0) -> 1
A15: Eswatini | B15: SWZ | C15: Lower middle income | D15: 816208 | E15: 0.50406918 | F15: 0.65116027 | G15: 0.43135622 | H15: 0.18166877 | J15: 10386.215 | K15: 26.249846 | L15: 139.83346 | M15: 63.403099 | N15: 89.3 | O15: 0.68629089 | P15: 0.99591334 | R15: 7.145326 | S15: 2.3167574 | T15: 1.0778075 | U15: 20.380197 | W15: 20 | X15: 100 | Z15: =IF(B15="KEN",1,0) -> 0 | AA15: =IF(D15>=Inputs!$D$10,1,0) -> 0 | AB15: =IF(AND(Z15=0,AA15=1),1,0) -> 0
A16: Ethiopia | B16: ETH | C16: Low income | D16: 78031387 | E16: 0.094548896 | F16: 0.48830277 | G16: 0.48470402 | H16: 0.059108578 | I16: 0.003159289 | J16: 2892.2222 | K16: 23.622284 | L16: 65.082509 | M16: 21.941299 | N16: 56.6 | O16: 4.7667108 | P16: 2.5835041 | Q16: 28.382151 | R16: 21.196837 | S16: 6.5095935 | W16: 60 | X16: 0 | Y16: 0.3291465 | Z16: =IF(B16="KEN",1,0) -> 0 | AA16: =IF(D16>=Inputs!$D$10,1,0) -> 1 | AB16: =IF(AND(Z16=0,AA16=1),1,0) -> 1
A17: Gabon | B17: GAB | C17: Upper middle income | D17: 1573811 | E17: 0.6164155 | F17: 0.68181256 | G17: 0.24831531 | H17: 0.20072601 | I17: 0.43577988 | J17: 18923.662 | K17: 91.863209 | L17: 125.33711 | M17: 68.720901 | N17: 95.1 | P17: 2.1563651 | Q17: 3.0111278 | R17: 2.9775832 | S17: 2.9568634 | T17: 8.2891387 | U17: 14.658932 | V17: 9.5710072 | W17: 20 | X17: 100 | Y17: 0.28795048 | Z17: =IF(B17="KEN",1,0) -> 0 | AA17: =IF(D17>=Inputs!$D$10,1,0) -> 0 | AB17: =IF(AND(Z17=0,AA17=1),1,0) -> 0
A18: Gambia, The | B18: GMB | C18: Low income | D18: 1598990 | E18: 0.19088544 | F18: 0.38160904 | G18: 0.30846912 | H18: 0.031812505 | J18: 3057.6842 | K18: 64.29941 | L18: 126.24377 | M18: 49.494301 | N18: 69 | O18: 21.999043 | P18: 2.2773026 | Q18: 13.349462 | R18: 9.1077921 | S18: 5.6536849 | T18: 2.0183379 | U18: 4.3523799 | V18: 16.752749 | W18: 20 | X18: 100 | Z18: =IF(B18="KEN",1,0) -> 0 | AA18: =IF(D18>=Inputs!$D$10,1,0) -> 0 | AB18: =IF(AND(Z18=0,AA18=1),1,0) -> 0
A19: Ghana | B19: GHA | C19: Lower middle income | D19: 21563813 | E19: 0.78281364 | F19: 0.81243025 | G19: 0.38741103 | H19: 0.27266012 | I19: 0.38947782 | J19: 7072.7988 | K19: 58.365487 | L19: 113.64797 | M19: 72.175697 | N19: 91.9 | O19: 3.634852 | P19: 1.8750001 | Q19: 30.737063 | R19: 29.770975 | S19: 4.2641364 | T19: 5.3116116 | U19: 18.222546 | V19: 9.5075287 | W19: 20 | X19: 100 | Y19: 0.30338907 | Z19: =IF(B19="KEN",1,0) -> 0 | AA19: =IF(D19>=Inputs!$D$10,1,0) -> 1 | AB19: =IF(AND(Z19=0,AA19=1),1,0) -> 1
A20: Guinea | B20: GIN | C20: Low income | D20: 8464230 | E20: 0.2582194 | F20: 0.36048025 | G20: 0.16903357 | H20: 0.084053328 | I20: 0.13780469 | J20: 4016.3419 | K20: 38.071304 | L20: 97.8795 | M20: 33.304699 | N20: 53.8 | O20: 2.4648244 | P20: 2.395958 | Q20: 8.807052 | S20: 4.954727 | T20: 10.359691 | U20: 15.60558 | V20: 16.38904 | W20: 20 | X20: 100 | Y20: 0.2899367 | Z20: =IF(B20="KEN",1,0) -> 0 | AA20: =IF(D20>=Inputs!$D$10,1,0) -> 1 | AB20: =IF(AND(Z20=0,AA20=1),1,0) -> 1
A21: Kenya | B21: KEN | C21: Lower middle income | D21: 34616135 | E21: 0.87499411 | F21: 0.90119917 | G21: 0.45427844 | H21: 0.55757002 | I21: 0.72931681 | J21: 5841.5987 | K21: 31.893783 | L21: 126.47771 | M21: 34.976225 | N21: 77 | O21: 4.152768 | P21: 1.9575143 | Q21: 6.6070159 | R21: 6.8925752 | S21: 5.0800565 | T21: 8.1622887 | U21: 11.89209 | V21: 8.2310026 | W21: 20 | X21: 100 | Y21: 0.13139349 | Z21: =IF(B21="KEN",1,0) -> 1 | AA21: =IF(D21>=Inputs!$D$10,1,0) -> 1 | AB21: =IF(AND(Z21=0,AA21=1),1,0) -> 0
A22: Lesotho | B22: LSO | C22: Lower middle income | D22: 1504222 | E22: 0.53472819 | F22: 0.61571044 | G22: 0.33529203 | H22: 0.15704578 | I22: 0.27641843 | J22: 2697.6274 | K22: 43.678033 | L22: 70.328049 | M22: 51.7966 | N22: 60.6 | O22: 19.89806 | P22: 1.1164489 | Q22: 6.9064892 | R22: 7.1760114 | S22: 3.1023819 | T22: 0.15852105 | V22: 7.9491495 | W22: 20 | X22: 100 | Y22: 0.15774394 | Z22: =IF(B22="KEN",1,0) -> 0 | AA22: =IF(D22>=Inputs!$D$10,1,0) -> 0 | AB22: =IF(AND(Z22=0,AA22=1),1,0) -> 0
A23: Liberia | B23: LBR | C23: Low income | D23: 3295997 | E23: 0.47529254 | F23: 0.52213933 | G23: 0.13883256 | H23: 0.064507532 | I23: 0.20843392 | J23: 1646.0586 | K23: 55.538799 | L23: 32.063889 | M23: 32.233601 | N23: 34.9 | O23: 21.275838 | P23: 2.1572535 | Q23: 8.6341376 | R23: 4.6988152 | S23: 4.5045722 | T23: 10.907886 | U23: 17.702246 | V23: 15.954297 | W23: 20 | X23: 100 | Y23: 0.17738734 | Z23: =IF(B23="KEN",1,0) -> 0 | AA23: =IF(D23>=Inputs!$D$10,1,0) -> 1 | AB23: =IF(AND(Z23=0,AA23=1),1,0) -> 1
A24: Madagascar | B24: MDG | C24: Low income | D24: 18851036 | E24: 0.19355017 | F24: 0.2445014 | G24: 0.094532663 | H24: 0.024181526 | I24: 0.12055303 | J24: 1659.1503 | K24: 32.433989 | L24: 75.456297 | M24: 18.6779 | N24: 42.5 | O24: 2.3092333 | P24: 2.4352476 | Q24: 8.549425 | R24: 5.5617471 | S24: 4.2304128 | T24: 9.6580478 | U24: 16.938854 | V24: 13.941049 | W24: 20 | X24: 100 | Y24: 0.15820575 | Z24: =IF(B24="KEN",1,0) -> 0 | AA24: =IF(D24>=Inputs!$D$10,1,0) -> 1 | AB24: =IF(AND(Z24=0,AA24=1),1,0) -> 1
A25: Malawi | B25: MWI | C25: Low income | D25: 12384937 | E25: 0.47399198 | F25: 0.50369673 | G25: 0.12406691 | H25: 0.10435313 | I25: 0.20302832 | J25: 1634.2466 | K25: 17.268504 | L25: 69.260531 | M25: 18.961599 | N25: 15.6 | O25: 1.976764 | P25: 2.5764147 | Q25: 27.307788 | R25: 18.257951 | S25: 1.513434 | T25: 7.6321638 | U25: 21.022972 | V25: 13.035874 | W25: 60 | X25: 100 | Y25: 0.2933758 | Z25: =IF(B25="KEN",1,0) -> 0 | AA25: =IF(D25>=Inputs!$D$10,1,0) -> 1 | AB25: =IF(AND(Z25=0,AA25=1),1,0) -> 1
A26: Mali | B26: MLI | C26: Low income | D26: 12725942 | E26: 0.48387616 | F26: 0.54745481 | G26: 0.18447528 | H26: 0.10205062 | I26: 0.24397649 | J26: 2917.9325 | K26: 31.607562 | L26: 112.11985 | M26: 36.801498 | N26: 49.5 | O26: 3.994336 | P26: 2.9411508 | Q26: 4.9622257 | R26: 2.9775832 | S26: 4.4945557 | T26: 15.61277 | U26: 18.255951 | V26: 13.030751 | W26: 20 | X26: 0 | Y26: 0.17791196 | Z26: =IF(B26="KEN",1,0) -> 0 | AA26: =IF(D26>=Inputs!$D$10,1,0) -> 1 | AB26: =IF(AND(Z26=0,AA26=1),1,0) -> 1
A27: Mauritius | B27: MUS | C27: Upper middle income | D27: 1070318 | E27: 0.10127067 | F27: 0.89598448 | G27: 0.89517981 | H27: 0.49889579 | I27: 0.056269371 | J27: 27844.896 | K27: 39.016215 | L27: 172.68357 | M27: 73.307935 | N27: 100 | O27: 1.9204279 | P27: -0.2299528 | Q27: 7.1437519 | R27: 3.576774 | S27: 5.9966894 | T27: 4.5491273 | U27: 8.7544094 | V27: 0.97831316 | W27: 20 | X27: 100 | Y27: 0.26039437 | Z27: =IF(B27="KEN",1,0) -> 0 | AA27: =IF(D27>=Inputs!$D$10,1,0) -> 0 | AB27: =IF(AND(Z27=0,AA27=1),1,0) -> 0
A28: Mozambique | B28: MOZ | C28: Low income | D28: 18581790 | E28: 0.45720986 | F28: 0.54385288 | G28: 0.25084035 | H28: 0.18474351 | I28: 0.21866821 | J28: 1500.7076 | K28: 36.433234 | L28: 49.50477 | M28: 20.5273 | N28: 36.9 | O28: 1.1731363 | P28: 2.9199405 | Q28: 7.1616483 | R28: -0.80393477 | S28: 4.0073592 | T28: 17.189939 | U28: 28.504936 | V28: 28.96317 | W28: 60 | X28: 0 | Y28: 0.1542557 | Z28: =IF(B28="KEN",1,0) -> 0 | AA28: =IF(D28>=Inputs!$D$10,1,0) -> 1 | AB28: =IF(AND(Z28=0,AA28=1),1,0) -> 1
A29: Namibia | B29: NAM | C29: Upper middle income | D29: 1858089 | E29: 0.48447358 | F29: 0.72918767 | G29: 0.62697495 | H29: 0.38572264 | I29: 0.4342947 | J29: 10276.369 | K29: 50.408803 | L29: 85.164899 | M29: 64.874603 | N29: 59.3 | O29: 0.70738677 | P29: 2.2371523 | Q29: 5.400085 | R29: 7.17602 | S29: 4.5007408 | T29: 1.2125731 | U29: 21.192866 | V29: 12.141007 | W29: 20 | X29: 100 | Y29: 0.17954216 | Z29: =IF(B29="KEN",1,0) -> 0 | AA29: =IF(D29>=Inputs!$D$10,1,0) -> 0 | AB29: =IF(AND(Z29=0,AA29=1),1,0) -> 0
A30: Niger | B30: NER | C30: Low income | D30: 13873697 | E30: 0.057003706 | F30: 0.14826899 | G30: 0.12666994 | H30: 0.024256929 | I30: 0.087172383 | J30: 1795.6527 | K30: 18.04974 | L30: 60.593986 | M30: 15.5576 | N30: 21.3 | O30: 3.2964746 | P30: 3.2810148 | Q30: 5.666237 | R30: 2.9775832 | S30: 7.7266634 | W30: 20 | X30: 0 | Y30: 0.01529781 | Z30: =IF(B30="KEN",1,0) -> 0 | AA30: =IF(D30>=Inputs!$D$10,1,0) -> 1 | AB30: =IF(AND(Z30=0,AA30=1),1,0) -> 1
A31: Nigeria | B31: NGA | C31: Lower middle income | D31: 133329232 | E31: 0.32790752 | F31: 0.63261351 | G31: 0.59727706 | H31: 0.28389282 | I31: 0.056061652 | J31: 7994.0375 | K31: 62.975568 | L31: 70.761906 | M31: 41.211399 | N31: 62.5 | O31: 8.7713441 | P31: 2.0829778 | Q31: 25.582799 | R31: 43.491915 | S31: 3.9019332 | T31: 15.540632 | U31: 18.118616 | V31: 9.0920021 | W31: 20 | X31: 0 | Y31: 0.27760098 | Z31: =IF(B31="KEN",1,0) -> 0 | AA31: =IF(D31>=Inputs!$D$10,1,0) -> 1 | AB31: =IF(AND(Z31=0,AA31=1),1,0) -> 1
A32: Senegal | B32: SEN | C32: Lower middle income | D32: 11094279 | E32: 0.66912649 | F32: 0.76460926 | G32: 0.48049595 | H32: 0.36972533 | I32: 0.31798091 | J32: 4477.8174 | K32: 55.236817 | L32: 123.89445 | M32: 60.117802 | N32: 82.9 | O32: 10.643413 | P32: 2.320586 | Q32: 5.4802668 | R32: 2.9775832 | S32: 4.8566895 | T32: 8.7454474 | U32: 21.964824 | V32: 10.762933 | W32: 20 | X32: 100 | Y32: 0.31431324 | Z32: =IF(B32="KEN",1,0) -> 0 | AA32: =IF(D32>=Inputs!$D$10,1,0) -> 1 | AB32: =IF(AND(Z32=0,AA32=1),1,0) -> 1
A33: Sierra Leone | B33: SLE | C33: Low income | D33: 5200533 | E33: 0.32195726 | F33: 0.38620521 | G33: 0.15013341 | H33: 0.052292713 | I33: 0.11018614 | J33: 3098.7629 | K33: 45.362682 | L33: 107.882 | M33: 25.105 | N33: 39.2 | O33: 4.602206 | P33: 2.1226891 | Q33: 34.494971 | R33: 35.66732 | S33: 5.1056 | T33: 2.6766051 | U33: 15.98818 | V33: 17.139349 | W33: 20 | X33: 100 | Y33: 0.22223874 | Z33: =IF(B33="KEN",1,0) -> 0 | AA33: =IF(D33>=Inputs!$D$10,1,0) -> 1 | AB33: =IF(AND(Z33=0,AA33=1),1,0) -> 1
A34: South Africa | B34: ZAF | C34: Upper middle income | D34: 46723498 | E34: 0.31623202 | F34: 0.81125966 | G34: 0.78433026 | H34: 0.46924837 | I34: 0.19016846 | J34: 13597.654 | K34: 63.691798 | L34: 179.33633 | M34: 78.357597 | N34: 90.2 | O34: 0.21323329 | P34: 1.2495143 | Q34: 5.825423 | R34: 7.1760114 | S34: 1.1330282 | T34: 15.914167 | U34: 14.539017 | V34: 9.426459 | W34: 20 | X34: 100 | Y34: 0.11795106 | Z34: =IF(B34="KEN",1,0) -> 0 | AA34: =IF(D34>=Inputs!$D$10,1,0) -> 1 | AB34: =IF(AND(Z34=0,AA34=1),1,0) -> 1
A35: Tanzania | B35: TZA | C35: Lower middle income | D35: 38155970 | E35: 0.52853984 | F35: 0.59827525 | G35: 0.21944173 | H35: 0.038577458 | I35: 0.38538031 | J35: 3713.2629 | K35: 36.168446 | L35: 126.55916 | M35: 31.1621 | N35: 52.4 | O35: 1.4176182 | P35: 2.8742667 | Q35: 3.7354839 | R35: 4.0922337 | S35: 5.0539477 | T35: 6.3849677 | U35: 15.232837 | V35: 20.663409 | W35: 100 | X35: 100 | Y35: 0.082005026 | Z35: =IF(B35="KEN",1,0) -> 0 | AA35: =IF(D35>=Inputs!$D$10,1,0) -> 1 | AB35: =IF(AND(Z35=0,AA35=1),1,0) -> 1
A36: Togo | B36: TGO | C36: Low income | D36: 5593530 | E36: 0.47991838 | F36: 0.57432953 | G36: 0.32442027 | H36: 0.13771111 | I36: 0.21457376 | J36: 3351.2499 | K36: 43.814849 | L36: 80.803555 | M36: 39.4832 | N36: 61.1 | P36: 2.1973646 | Q36: 5.4398267 | R36: 2.9775832 | S36: 6.3395268 | T36: 26.293977 | U36: 24.039604 | V36: 4.9774876 | W36: 20 | X36: 100 | Y36: 0.38484391 | Z36: =IF(B36="KEN",1,0) -> 0 | AA36: =IF(D36>=Inputs!$D$10,1,0) -> 1 | AB36: =IF(AND(Z36=0,AA36=1),1,0) -> 1
A37: Uganda | B37: UGA | C37: Low income | D37: 27277834 | E37: 0.67738295 | F37: 0.72827376 | G37: 0.26173324 | H37: 0.11671008 | I37: 0.50581243 | J37: 2879.6701 | K37: 31.27777 | L37: 83.165031 | M37: 8.9498311 | N37: 55.3 | O37: 2.6514081 | P37: 2.7537317 | Q37: 5.2900391 | R37: 1.5453343 | S37: 5.3268585 | T37: 12.903442 | U37: 12.607208 | V37: 16.129261 | W37: 100 | X37: 100 | Y37: 0.12137563 | Z37: =IF(B37="KEN",1,0) -> 0 | AA37: =IF(D37>=Inputs!$D$10,1,0) -> 1 | AB37: =IF(AND(Z37=0,AA37=1),1,0) -> 1
A38: Zambia | B38: ZMB | C38: Low income | D38: 12029200 | E38: 0.69310751 | F38: 0.72702425 | G38: 0.24072373 | H38: 0.19196639 | I38: 0.27842392 | J38: 3708.069 | K38: 45.470384 | L38: 108.70478 | M38: 17.101 | N38: 53.6 | O38: 1.3212312 | P38: 2.8118226 | Q38: 12.287787 | R38: 8.9273555 | S38: 4.7997382 | T38: 7.5237869 | U38: 25.333009 | V38: 5.7597968 | W38: 60 | X38: 100 | Y38: 0.26224857 | Z38: =IF(B38="KEN",1,0) -> 0 | AA38: =IF(D38>=Inputs!$D$10,1,0) -> 1 | AB38: =IF(AND(Z38=0,AA38=1),1,0) -> 1
A39: Zimbabwe | B39: ZWE | C39: Lower middle income | D39: 9588258 | E39: 0.43331737 | F39: 0.49521602 | G39: 0.21566153 | H39: 0.29098485 | I39: 0.48581632 | J39: 5211.8976 | K39: 39.893372 | L39: 94.245175 | M39: 41.642799 | N39: 62 | O39: 8.4531023 | P39: 1.7804823 | Q39: 104.70517 | R39: 120.26093 | S39: 4.3888755 | T39: 7.1863431 | U39: 15.214052 | V39: 14.891015 | W39: 20 | X39: 40 | Y39: 0.090852221 | Z39: =IF(B39="KEN",1,0) -> 0 | AA39: =IF(D39>=Inputs!$D$10,1,0) -> 1 | AB39: =IF(AND(Z39=0,AA39=1),1,0) -> 1

Sheet Forecast
A1: Adoption forecast to 2030
A2: Logistic diffusion: logit(adoption) rises by a common yearly growth rate (Inputs), scaled by the scenario multiplier, capped at the ceiling.
A5: Country | B5: ISO3 | C5: Candidate | D5: Mobile money 2024 | E5: logit(adoption 2024) | F5: Growth of logit per year | G5: Adults 2030 | H5: Users at 2024 penetration, 2030 | I5: Adoption 2030 Low | J5: Adoption 2030 Base | K5: Adoption 2030 High | L5: Users 2030 Low | M5: Users 2030 Base | N5: Users 2030 High | O5: New users vs 2024 penetration, Low | P5: New users Base | Q5: New users High
A6: =Data!A6 -> Benin | B6: =Data!B6 -> BEN | C6: =Data!AB6 -> 1 | D6: =Data!E6 -> 0.44872852 | E6: =LN(MIN(0.995,MAX(0.005,D6))/(1-MIN(0.995,MAX(0.005,D6)))) -> -0.20580932 | F6: =MIN(Inputs!$D$14,MAX(Inputs!$D$13,(1-Inputs!$D$12)*Inputs!$D$11+Inputs!$D$12*IF(Data!Y6="",Inputs!$D$11,Data!Y6))) -> 0.17872706 | G6: =Data!D6*(1+Data!P6/100)^Inputs!$D$8 -> 9496898.8 | H6: =G6*D6 -> 4261529.3 | I6: =MIN(1/(1+EXP(-(E6+F6*Inputs!$C$16*Inputs!$D$8))),MAX(Inputs!$D$9,D6)) -> 0.58184985 | J6: =MIN(1/(1+EXP(-(E6+F6*Inputs!$D$16*Inputs!$D$8))),MAX(Inputs!$D$9,D6)) -> 0.70402795 | K6: =MIN(1/(1+EXP(-(E6+F6*Inputs!$E$16*Inputs!$D$8))),MAX(Inputs!$D$9,D6)) -> 0.80261741 | L6: =G6*I6 -> 5525769.2 | M6: =G6*J6 -> 6686082.2 | N6: =G6*K6 -> 7622376.3 | O6: =MAX(0,L6-H6) -> 1264239.8 | P6: =MAX(0,M6-H6) -> 2424552.9 | Q6: =MAX(0,N6-H6) -> 3360847
A7: =Data!A7 -> Botswana | B7: =Data!B7 -> BWA | C7: =Data!AB7 -> 0 | D7: =Data!E7 -> 0.51617816 | E7: =LN(MIN(0.995,MAX(0.005,D7))/(1-MIN(0.995,MAX(0.005,D7)))) -> 0.064735226 | F7: =MIN(Inputs!$D$14,MAX(Inputs!$D$13,(1-Inputs!$D$12)*Inputs!$D$11+Inputs!$D$12*IF(Data!Y7="",Inputs!$D$11,Data!Y7))) -> 0.17872706 | G7: =Data!D7*(1+Data!P7/100)^Inputs!$D$8 -> 1851283.3 | H7: =G7*D7 -> 955591.99 | I7: =MIN(1/(1+EXP(-(E7+F7*Inputs!$C$16*Inputs!$D$8))),MAX(Inputs!$D$9,D7)) -> 0.64586594 | J7: =MIN(1/(1+EXP(-(E7+F7*Inputs!$D$16*Inputs!$D$8))),MAX(Inputs!$D$9,D7)) -> 0.75714636 | K7: =MIN(1/(1+EXP(-(E7+F7*Inputs!$E$16*Inputs!$D$8))),MAX(Inputs!$D$9,D7)) -> 0.84201248 | L7: =G7*I7 -> 1195680.8 | M7: =G7*J7 -> 1401692.4 | N7: =G7*K7 -> 1558803.6 | O7: =MAX(0,L7-H7) -> 240088.82 | P7: =MAX(0,M7-H7) -> 446100.39 | Q7: =MAX(0,N7-H7) -> 603211.63
A8: =Data!A8 -> Burkina Faso | B8: =Data!B8 -> BFA | C8: =Data!AB8 -> 1 | D8: =Data!E8 -> 0.44157364 | E8: =LN(MIN(0.995,MAX(0.005,D8))/(1-MIN(0.995,MAX(0.005,D8)))) -> -0.23477795 | F8: =MIN(Inputs!$D$14,MAX(Inputs!$D$13,(1-Inputs!$D$12)*Inputs!$D$11+Inputs!$D$12*IF(Data!Y8="",Inputs!$D$11,Data!Y8))) -> 0.17872706 | G8: =Data!D8*(1+Data!P8/100)^Inputs!$D$8 -> 15153214 | H8: =G8*D8 -> 6691259.7 | I8: =MIN(1/(1+EXP(-(E8+F8*Inputs!$C$16*Inputs!$D$8))),MAX(Inputs!$D$9,D8)) -> 0.57478551 | J8: =MIN(1/(1+EXP(-(E8+F8*Inputs!$D$16*Inputs!$D$8))),MAX(Inputs!$D$9,D8)) -> 0.69795622 | K8: =MIN(1/(1+EXP(-(E8+F8*Inputs!$E$16*Inputs!$D$8))),MAX(Inputs!$D$9,D8)) -> 0.79798786 | L8: =G8*I8 -> 8709847.6 | M8: =G8*J8 -> 10576280 | N8: =G8*K8 -> 12092080 | O8: =MAX(0,L8-H8) -> 2018587.9 | P8: =MAX(0,M8-H8) -> 3885020 | Q8: =MAX(0,N8-H8) -> 5400820.8
A9: =Data!A9 -> Cameroon | B9: =Data!B9 -> CMR | C9: =Data!AB9 -> 1 | D9: =Data!E9 -> 0.55065452 | E9: =LN(MIN(0.995,MAX(0.005,D9))/(1-MIN(0.995,MAX(0.005,D9)))) -> 0.20331557 | F9: =MIN(Inputs!$D$14,MAX(Inputs!$D$13,(1-Inputs!$D$12)*Inputs!$D$11+Inputs!$D$12*IF(Data!Y9="",Inputs!$D$11,Data!Y9))) -> 0.17872706 | G9: =Data!D9*(1+Data!P9/100)^Inputs!$D$8 -> 19289633 | H9: =G9*D9 -> 10621924 | I9: =MIN(1/(1+EXP(-(E9+F9*Inputs!$C$16*Inputs!$D$8))),MAX(Inputs!$D$9,D9)) -> 0.6768858 | J9: =MIN(1/(1+EXP(-(E9+F9*Inputs!$D$16*Inputs!$D$8))),MAX(Inputs!$D$9,D9)) -> 0.78171317 | K9: =MIN(1/(1+EXP(-(E9+F9*Inputs!$E$16*Inputs!$D$8))),MAX(Inputs!$D$9,D9)) -> 0.85958642 | L9: =G9*I9 -> 13056879 | M9: =G9*J9 -> 15078960 | N9: =G9*K9 -> 16581107 | O9: =MAX(0,L9-H9) -> 2434955.1 | P9: =MAX(0,M9-H9) -> 4457036.6 | Q9: =MAX(0,N9-H9) -> 5959182.9
A10: =Data!A10 -> Chad | B10: =Data!B10 -> TCD | C10: =Data!AB10 -> 1 | D10: =Data!E10 -> 0.13335894 | E10: =LN(MIN(0.995,MAX(0.005,D10))/(1-MIN(0.995,MAX(0.005,D10)))) -> -1.8715806 | F10: =MIN(Inputs!$D$14,MAX(Inputs!$D$13,(1-Inputs!$D$12)*Inputs!$D$11+Inputs!$D$12*IF(Data!Y10="",Inputs!$D$11,Data!Y10))) -> 0.17872706 | G10: =Data!D10*(1+Data!P10/100)^Inputs!$D$8 -> 13748917 | H10: =G10*D10 -> 1833541 | I10: =MIN(1/(1+EXP(-(E10+F10*Inputs!$C$16*Inputs!$D$8))),MAX(Inputs!$D$9,D10)) -> 0.20826765 | J10: =MIN(1/(1+EXP(-(E10+F10*Inputs!$D$16*Inputs!$D$8))),MAX(Inputs!$D$9,D10)) -> 0.31019278 | K10: =MIN(1/(1+EXP(-(E10+F10*Inputs!$E$16*Inputs!$D$8))),MAX(Inputs!$D$9,D10)) -> 0.43461729 | L10: =G10*I10 -> 2863454.5 | M10: =G10*J10 -> 4264814.6 | N10: =G10*K10 -> 5975516.9 | O10: =MAX(0,L10-H10) -> 1029913.5 | P10: =MAX(0,M10-H10) -> 2431273.6 | Q10: =MAX(0,N10-H10) -> 4141975.9
A11: =Data!A11 -> Comoros | B11: =Data!B11 -> COM | C11: =Data!AB11 -> 0 | D11: =Data!E11 -> 0.14093786 | E11: =LN(MIN(0.995,MAX(0.005,D11))/(1-MIN(0.995,MAX(0.005,D11)))) -> -1.8075221 | F11: =MIN(Inputs!$D$14,MAX(Inputs!$D$13,(1-Inputs!$D$12)*Inputs!$D$11+Inputs!$D$12*IF(Data!Y11="",Inputs!$D$11,Data!Y11))) -> 0.17872706 | G11: =Data!D11*(1+Data!P11/100)^Inputs!$D$8 -> 595686.66 | H11: =G11*D11 -> 83954.806 | I11: =MIN(1/(1+EXP(-(E11+F11*Inputs!$C$16*Inputs!$D$8))),MAX(Inputs!$D$9,D11)) -> 0.21902779 | J11: =MIN(1/(1+EXP(-(E11+F11*Inputs!$D$16*Inputs!$D$8))),MAX(Inputs!$D$9,D11)) -> 0.32406347 | K11: =MIN(1/(1+EXP(-(E11+F11*Inputs!$E$16*Inputs!$D$8))),MAX(Inputs!$D$9,D11)) -> 0.45041883 | L11: =G11*I11 -> 130471.93 | M11: =G11*J11 -> 193040.29 | N11: =G11*K11 -> 268308.49 | O11: =MAX(0,L11-H11) -> 46517.127 | P11: =MAX(0,M11-H11) -> 109085.48 | Q11: =MAX(0,N11-H11) -> 184353.69
A12: =Data!A12 -> Congo, Dem. Rep. | B12: =Data!B12 -> COD | C12: =Data!AB12 -> 1 | D12: =Data!E12 -> 0.35118239 | E12: =LN(MIN(0.995,MAX(0.005,D12))/(1-MIN(0.995,MAX(0.005,D12)))) -> -0.61384594 | F12: =MIN(Inputs!$D$14,MAX(Inputs!$D$13,(1-Inputs!$D$12)*Inputs!$D$11+Inputs!$D$12*IF(Data!Y12="",Inputs!$D$11,Data!Y12))) -> 0.17872706 | G12: =Data!D12*(1+Data!P12/100)^Inputs!$D$8 -> 69068438 | H12: =G12*D12 -> 24255619 | I12: =MIN(1/(1+EXP(-(E12+F12*Inputs!$C$16*Inputs!$D$8))),MAX(Inputs!$D$9,D12)) -> 0.48059357 | J12: =MIN(1/(1+EXP(-(E12+F12*Inputs!$D$16*Inputs!$D$8))),MAX(Inputs!$D$9,D12)) -> 0.61266217 | K12: =MIN(1/(1+EXP(-(E12+F12*Inputs!$E$16*Inputs!$D$8))),MAX(Inputs!$D$9,D12)) -> 0.73001479 | L12: =G12*I12 -> 33193847 | M12: =G12*J12 -> 42315619 | N12: =G12*K12 -> 50420981 | O12: =MAX(0,L12-H12) -> 8938227.9 | P12: =MAX(0,M12-H12) -> 18060000 | Q12: =MAX(0,N12-H12) -> 26165362
A13: =Data!A13 -> Congo, Rep. | B13: =Data!B13 -> COG | C13: =Data!AB13 -> 1 | D13: =Data!E13 -> 0.51592118 | E13: =LN(MIN(0.995,MAX(0.005,D13))/(1-MIN(0.995,MAX(0.005,D13)))) -> 0.063706246 | F13: =MIN(Inputs!$D$14,MAX(Inputs!$D$13,(1-Inputs!$D$12)*Inputs!$D$11+Inputs!$D$12*IF(Data!Y13="",Inputs!$D$11,Data!Y13))) -> 0.17872706 | G13: =Data!D13*(1+Data!P13/100)^Inputs!$D$8 -> 4213613.3 | H13: =G13*D13 -> 2173892.3 | I13: =MIN(1/(1+EXP(-(E13+F13*Inputs!$C$16*Inputs!$D$8))),MAX(Inputs!$D$9,D13)) -> 0.64563055 | J13: =MIN(1/(1+EXP(-(E13+F13*Inputs!$D$16*Inputs!$D$8))),MAX(Inputs!$D$9,D13)) -> 0.7569571 | K13: =MIN(1/(1+EXP(-(E13+F13*Inputs!$E$16*Inputs!$D$8))),MAX(Inputs!$D$9,D13)) -> 0.84187555 | L13: =G13*I13 -> 2720437.5 | M13: =G13*J13 -> 3189524.5 | N13: =G13*K13 -> 3547338 | O13: =MAX(0,L13-H13) -> 546545.15 | P13: =MAX(0,M13-H13) -> 1015632.2 | Q13: =MAX(0,N13-H13) -> 1373445.7
A14: =Data!A14 -> Cote d'Ivoire | B14: =Data!B14 -> CIV | C14: =Data!AB14 -> 1 | D14: =Data!E14 -> 0.53381779 | E14: =LN(MIN(0.995,MAX(0.005,D14))/(1-MIN(0.995,MAX(0.005,D14)))) -> 0.13547799 | F14: =MIN(Inputs!$D$14,MAX(Inputs!$D$13,(1-Inputs!$D$12)*Inputs!$D$11+Inputs!$D$12*IF(Data!Y14="",Inputs!$D$11,Data!Y14))) -> 0.17872706 | G14: =Data!D14*(1+Data!P14/100)^Inputs!$D$8 -> 21145066 | H14: =G14*D14 -> 11287612 | I14: =MIN(1/(1+EXP(-(E14+F14*Inputs!$C$16*Inputs!$D$8))),MAX(Inputs!$D$9,D14)) -> 0.66187458 | J14: =MIN(1/(1+EXP(-(E14+F14*Inputs!$D$16*Inputs!$D$8))),MAX(Inputs!$D$9,D14)) -> 0.7699166 | K14: =MIN(1/(1+EXP(-(E14+F14*Inputs!$E$16*Inputs!$D$8))),MAX(Inputs!$D$9,D14)) -> 0.85119716 | L14: =G14*I14 -> 13995382 | M14: =G14*J14 -> 16279938 | N14: =G14*K14 -> 17998620 | O14: =MAX(0,L14-H14) -> 2707769.3 | P14: =MAX(0,M14-H14) -> 4992325.1 | Q14: =MAX(0,N14-H14) -> 6711007.8
